<!-- Gripper and Sensor body.... This file is for use with UR5.xml/-->
<mujoco>
<body 	name="sensor_body" pos="0 0 0">
	<geom 	name="sensor_body_g" type="cylinder" size="0.025 0.0135" rgba="0.1 0.9 0.1 1"
		mass="0.215" contype="1" conaffinity="1"/>
	<site   name="sensor_site" type="cylinder" size="0.025 0.0135" pos="0 0 0"/>

	<body name="gripper_base_link" euler="0 0 0" pos="0 0 0.0135">
      	<inertial euler="0 0 0"  pos="0 0 0" mass="0.25"
		  diaginertia="1 1 1" />
      	<geom name="gripper_base_g" material="GriMat"  type="mesh" mesh="WSG50_110"/>
		
		<body name="gripper_left_link" euler="0 0 0" pos="0 0 0">
	      	<inertial euler="0 0 0"  pos="0 0 0" mass="0.1"
			  diaginertia="1 1 1" />
	      	<geom name="gripper_left_g" material="FinMat"  type="mesh" mesh="GUIDE_WSG50_110"/>
		<joint  name="gripper_base_left_finger_joint" type="slide" axis="1 0 0" limited="true" frictional="true"
			range="-0.055 -0.0027" 			
			damping="1.0" frictionloss="0"/>
	
			<body name="gripper_left_finger_link"  euler="0 0 0" pos="0 0 0.023">
		      	<inertial euler="0 0 0"  pos="0 0 0" mass="0.1"
				  diaginertia="1 1 1" />
		      	<geom name="gripper_left_finger_g" material="FinMat"  type="mesh" mesh="WSG-FMF" />
			</body>
		</body>

		<body name="gripper_right_link" euler="0 0 3.14159" pos="0 0 0">
	      	<inertial euler="0 0 0"  pos="0 0 0" mass="0.1"
			  diaginertia="1 1 1" />
	      	<geom name="gripper_right_g" material="FinMat"  type="mesh" mesh="GUIDE_WSG50_110" />
		<joint  name="gripper_base_right_finger_joint" type="slide" axis="-1 0 0" limited="true" frictional="true"
			range="0.0027 0.055" 			
			damping="1.0" frictionloss="0"/>
	
			<body name="gripper_right_finger_link"  euler="0 0 0" pos="0 0 0.023">
		      	<inertial euler="0 0 0"  pos="0 0 0" mass="0.1"
				  diaginertia="1 1 1" />
		      	<geom name="gripper_right_finger_g" material="FinMat"  type="mesh" mesh="WSG-FMF" />
			</body>
		</body>
	
	</body>
</body> 
</mujoco>
